{"trial_id": "2", "hyperparameters": {"space": [{"class_name": "Choice", "config": {"name": "optimizer", "default": "adam", "conditions": [], "values": ["adam", "sgd", "rmsprop", "adadelta"], "ordered": false}}], "values": {"optimizer": "sgd"}}, "metrics": {"metrics": {"accuracy": {"direction": "max", "observations": [{"value": [0.6889250874519348], "step": 4}]}, "loss": {"direction": "min", "observations": [{"value": [0.6200931072235107], "step": 4}]}, "val_accuracy": {"direction": "max", "observations": [{"value": [0.6948052048683167], "step": 4}]}, "val_loss": {"direction": "min", "observations": [{"value": [0.6181642413139343], "step": 4}]}}}, "score": 0.6948052048683167, "best_step": 4, "status": "COMPLETED", "message": "Traceback (most recent call last):\n  File \"C:\\Users\\ritik\\anaconda3\\Lib\\site-packages\\keras_tuner\\src\\engine\\base_tuner.py\", line 274, in _try_run_and_update_trial\n    self._run_and_update_trial(trial, *fit_args, **fit_kwargs)\n  File \"C:\\Users\\ritik\\anaconda3\\Lib\\site-packages\\keras_tuner\\src\\engine\\base_tuner.py\", line 239, in _run_and_update_trial\n    results = self.run_trial(trial, *fit_args, **fit_kwargs)\n              ^^^^^^^^^^^^^^^^^^^^^^^^^^^^^^^^^^^^^^^^^^^^^^\n  File \"C:\\Users\\ritik\\anaconda3\\Lib\\site-packages\\keras_tuner\\src\\engine\\tuner.py\", line 314, in run_trial\n    obj_value = self._build_and_fit_model(trial, *args, **copied_kwargs)\n                ^^^^^^^^^^^^^^^^^^^^^^^^^^^^^^^^^^^^^^^^^^^^^^^^^^^^^^^^\n  File \"C:\\Users\\ritik\\anaconda3\\Lib\\site-packages\\keras_tuner\\src\\engine\\tuner.py\", line 233, in _build_and_fit_model\n    results = self.hypermodel.fit(hp, model, *args, **kwargs)\n              ^^^^^^^^^^^^^^^^^^^^^^^^^^^^^^^^^^^^^^^^^^^^^^^\n  File \"C:\\Users\\ritik\\anaconda3\\Lib\\site-packages\\keras_tuner\\src\\engine\\hypermodel.py\", line 149, in fit\n    return model.fit(*args, **kwargs)\n           ^^^^^^^^^^^^^^^^^^^^^^^^^^\n  File \"C:\\Users\\ritik\\anaconda3\\Lib\\site-packages\\keras\\src\\utils\\traceback_utils.py\", line 122, in error_handler\n    raise e.with_traceback(filtered_tb) from None\n  File \"C:\\Users\\ritik\\anaconda3\\Lib\\site-packages\\keras\\src\\utils\\traceback_utils.py\", line 119, in error_handler\n    filtered_tb = _process_traceback_frames(e.__traceback__)\n                  ^^^^^^^^^^^^^^^^^^^^^^^^^^^^^^^^^^^^^^^^^^\nTypeError: TensorFlowTrainer.fit() got an unexpected keyword argument 'epoch'\n"}